Workbook

Sheet README
B2: YouMakeTV — 5-Year Business & Financial Model
B5: HOW TO USE THIS WORKBOOK
B6: 1. Go to the "Assumptions" sheet and set the Scenario switch (cell D3): 1 = Conservative, 2 = Base, 3 = Aggressive.
B7: 2. Every yellow cell is an editable input. All white/grey cells are live formulas — do not overtype them.
B8: 3. The "Model" sheet recalculates the full 5-year P&L, cash position and KPIs from the Assumptions sheet.
B9: 4. Future financing rounds (Series A / B) are editable inputs on the Model sheet, row "New funding".
B11: SHEETS
B12: • Assumptions — every driver of the model, with Conservative / Base / Aggressive values side by side.
B13: • Model — 5-year users, revenue, creator payouts, COGS, OPEX, EBITDA, cash and runway.
B14: • Market — TAM / SAM / SOM with CAGR and sources.
B15: • Competition — competitive landscape and positioning matrix.
B16: • GTM-Creators — creator acquisition channels: reach, cost, conversion, expected signups, CAC.
... B33: All projections are illustrative and depend on the assumptions herein. Prepared June 2026.

Sheet Assumptions
B1: Assumptions & Scenario Drivers
B3: Scenario switch (1 = Conservative, 2 = Base, 3 = Aggressive): | D3: 2 | E3: =CHOOSE($D$3,"CONSERVATIVE","BASE","AGGRESSIVE") -> BASE
B5: Driver | C5: Unit | D5: Conservative | E5: Base | F5: Aggressive | G5: ACTIVE
B6: PRICING & TAKE RATES
B7: Avg. pay-per-view price | C7: $ / film | D7: 3.99 | E7: 4.99 | F7: 5.99 | G7: =CHOOSE($D$3,D7,E7,F7) -> 4.99
B8: YouMake+ subscription price | C8: $ / month | D8: 6.99 | E8: 7.99 | F8: 8.99 | G8: =CHOOSE($D$3,D8,E8,F8) -> 7.99
B9: Creator share of PPV (blended across tiers) | C9: % of PPV | D9: 0.4 | E9: 0.36 | F9: 0.33 | G9: =CHOOSE($D$3,D9,E9,F9) -> 0.36
B10: Creator pool share of subscription revenue | C10: % of subs rev | D10: 0.5 | E10: 0.45 | F10: 0.4 | G10: =CHOOSE($D$3,D10,E10,F10) -> 0.45
B11: Payment processing cost | C11: % of gross billings | D11: 0.055 | E11: 0.045 | F11: 0.04 | G11: =CHOOSE($D$3,D11,E11,F11) -> 0.045
B12: Ad net ARPU at maturity (per registered user) | C12: $ / user / yr | D12: 1.2 | E12: 2.4 | F12: 4 | G12: =CHOOSE($D$3,D12,E12,F12) -> 2.4
B13: Featured placement / promo rev per active creator | C13: $ / creator / yr | D13: 15 | E13: 30 | F13: 60 | G13: =CHOOSE($D$3,D13,E13,F13) -> 30
B14: Registered users who buy PPV | C14: % of registered | D14: 0.06 | E14: 0.08 | F14: 0.1 | G14: =CHOOSE($D$3,D14,E14,F14) -> 0.08
B15: VIEWER GROWTH & ACQUISITION
B16: Blended paid CAC per gross subscriber add (Year 1) | C16: $ | D16: 35 | E16: 25 | F16: 20 | G16: =CHOOSE($D$3,D16,E16,F16) -> 25
B17: Annual CAC improvement factor | C17: x / yr | D17: 0.95 | E17: 0.9 | F17: 0.88 | G17: =CHOOSE($D$3,D17,E17,F17) -> 0.9
B18: Viewing hours per subscriber | C18: hrs / month | D18: 8 | E18: 10 | F18: 12 | G18: =CHOOSE($D$3,D18,E18,F18) -> 10
B19: Streaming + delivery cost | C19: $ / hour | D19: 0.05 | E19: 0.04 | F19: 0.03 | G19: =CHOOSE($D$3,D19,E19,F19) -> 0.04
B20: CREATOR SUPPLY
B21: Creator activation (signs up AND publishes) | C21: % of signups | D21: 0.45 | E21: 0.55 | F21: 0.65 | G21: =CHOOSE($D$3,D21,E21,F21) -> 0.55
B22: Films published per active creator per year | C22: films / yr | D22: 2.5 | E22: 3.5 | F22: 4.5 | G22: =CHOOSE($D$3,D22,E22,F22) -> 3.5
B23: Creator acquisition cost | C23: $ / signup | D23: 60 | E23: 40 | F23: 30 | G23: =CHOOSE($D$3,D23,E23,F23) -> 40
B24: Moderation + review cost per film | C24: $ / film | D24: 12 | E24: 8 | F24: 6 | G24: =CHOOSE($D$3,D24,E24,F24) -> 8
B25: Storage + transcode per film in catalog | C25: $ / film / yr | D25: 6 | E25: 4 | F25: 3 | G25: =CHOOSE($D$3,D25,E25,F25) -> 4
B26: TEAM & OVERHEAD
B27: Avg. fully-loaded cost per employee | C27: $K / yr | D27: 155 | E27: 145 | F27: 135 | G27: =CHOOSE($D$3,D27,E27,F27) -> 145
B28: Legal, compliance & content policy (Year 1) | C28: $K / yr | D28: 80 | E28: 120 | F28: 180 | G28: =CHOOSE($D$3,D28,E28,F28) -> 120
B29: Customer support cost | C29: % of net rev (min $60K) | D29: 0.06 | E29: 0.05 | F29: 0.04 | G29: =CHOOSE($D$3,D29,E29,F29) -> 0.05
B30: G&A, tools, insurance, office | C30: % of payroll | D30: 0.15 | E30: 0.12 | F30: 0.1 | G30: =CHOOSE($D$3,D30,E30,F30) -> 0.12
B31: Funding raised at start of Year 1 | C31: $K | D31: 2000 | E31: 4000 | F31: 7000 | G31: =CHOOSE($D$3,D31,E31,F31) -> 4000
B32: PER-YEAR DRIVERS (each row = one year)
B33: Registered viewers, end of year — Year 1 | C33: 000s | D33: 15 | E33: 30 | F33: 50 | G33: =CHOOSE($D$3,D33,E33,F33) -> 30
B34: Registered viewers, end of year — Year 2 | C34: 000s | D34: 60 | E34: 120 | F34: 250 | G34: =CHOOSE($D$3,D34,E34,F34) -> 120
B35: Registered viewers, end of year — Year 3 | C35: 000s | D35: 180 | E35: 400 | F35: 900 | G35: =CHOOSE($D$3,D35,E35,F35) -> 400
B36: Registered viewers, end of year — Year 4 | C36: 000s | D36: 420 | E36: 1000 | F36: 2500 | G36: =CHOOSE($D$3,D36,E36,F36) -> 1000
B37: Registered viewers, end of year — Year 5 | C37: 000s | D37: 800 | E37: 2000 | F37: 5000 | G37: =CHOOSE($D$3,D37,E37,F37) -> 2000
B38: Gross subscriber additions — Year 1 | C38: 000s / yr | D38: 1.5 | E38: 2.5 | F38: 4 | G38: =CHOOSE($D$3,D38,E38,F38) -> 2.5
B39: Gross subscriber additions — Year 2 | C39: 000s / yr | D39: 6 | E39: 12 | F39: 25 | G39: =CHOOSE($D$3,D39,E39,F39) -> 12
B40: Gross subscriber additions — Year 3 | C40: 000s / yr | D40: 18 | E40: 40 | F40: 90 | G40: =CHOOSE($D$3,D40,E40,F40) -> 40
B41: Gross subscriber additions — Year 4 | C41: 000s / yr | D41: 40 | E41: 95 | F41: 220 | G41: =CHOOSE($D$3,D41,E41,F41) -> 95
B42: Gross subscriber additions — Year 5 | C42: 000s / yr | D42: 75 | E42: 190 | F42: 450 | G42: =CHOOSE($D$3,D42,E42,F42) -> 190
...

Sheet Model
B1: YouMakeTV — 5-Year Operating Model
B2: ="Active scenario: "&CHOOSE(Assumptions!$D$3,"CONSERVATIVE","BASE","AGGRESSIVE") -> Active scenario: BASE
C4: Year 1 | D4: Year 2 | E4: Year 3 | F4: Year 4 | G4: Year 5
B5: SUPPLY — CREATORS & CATALOG
B6: New creator signups | C6: =Assumptions!$G$58 -> 500 | D6: =Assumptions!$G$59 -> 1200 | E6: =Assumptions!$G$60 -> 2800 | F6: =Assumptions!$G$61 -> 5000 | G6: =Assumptions!$G$62 -> 8000
B7: Active creators (cumulative × activation) | C7: =SUM($C$6:C6)*Assumptions!$G$21 -> 275 | D7: =SUM($C$6:D6)*Assumptions!$G$21 -> 935 | E7: =SUM($C$6:E6)*Assumptions!$G$21 -> 2475 | F7: =SUM($C$6:F6)*Assumptions!$G$21 -> 5225 | G7: =SUM($C$6:G6)*Assumptions!$G$21 -> 9625
B8: New films published | C8: =C7*Assumptions!$G$22 -> 962.5 | D8: =D7*Assumptions!$G$22 -> 3272.5 | E8: =E7*Assumptions!$G$22 -> 8662.5 | F8: =F7*Assumptions!$G$22 -> 18287.5 | G8: =G7*Assumptions!$G$22 -> 33687.5
B9: Catalog size (cumulative films) | C9: =SUM($C$8:C8) -> 962.5 | D9: =SUM($C$8:D8) -> 4235 | E9: =SUM($C$8:E8) -> 12897.5 | F9: =SUM($C$8:F8) -> 31185 | G9: =SUM($C$8:G8) -> 64872.5
B10: DEMAND — VIEWERS & SUBSCRIBERS
B11: Registered viewers (end of year) | C11: =Assumptions!$G$33*1000 -> 30000 | D11: =Assumptions!$G$34*1000 -> 120000 | E11: =Assumptions!$G$35*1000 -> 400000 | F11: =Assumptions!$G$36*1000 -> 1000000 | G11: =Assumptions!$G$37*1000 -> 2000000
B12: Gross subscriber additions | C12: =Assumptions!$G$38*1000 -> 2500 | D12: =Assumptions!$G$39*1000 -> 12000 | E12: =Assumptions!$G$40*1000 -> 40000 | F12: =Assumptions!$G$41*1000 -> 95000 | G12: =Assumptions!$G$42*1000 -> 190000
B13: Monthly churn | C13: =Assumptions!$G$43 -> 0.08 | D13: =Assumptions!$G$44 -> 0.07 | E13: =Assumptions!$G$45 -> 0.065 | F13: =Assumptions!$G$46 -> 0.06 | G13: =Assumptions!$G$47 -> 0.055
B14: Subscribers — end of year | C14: =C12*(1-C13)^6 -> 1515.8875 | D14: =C14*(1-D13)^12+D12*(1-D13)^6 -> 8398.4271 | E14: =D14*(1-E13)^12+E12*(1-E13)^6 -> 30474.924 | F14: =E14*(1-F13)^12+F12*(1-F13)^6 -> 80041.264 | G14: =F14*(1-G13)^12+G12*(1-G13)^6 -> 175911.69
B15: Subscribers — average | C15: =C14/2 -> 757.94375 | D15: =(C14+D14)/2 -> 4957.1573 | E15: =(D14+E14)/2 -> 19436.675 | F15: =(E14+F14)/2 -> 55258.094 | G15: =(F14+G14)/2 -> 127976.48
B16: REVENUE — GROSS BILLINGS
B17: Subscription billings | C17: =C15*Assumptions!$G$8*12 -> 72671.647 | D17: =D15*Assumptions!$G$8*12 -> 475292.24 | E17: =E15*Assumptions!$G$8*12 -> 1863588.4 | F17: =F15*Assumptions!$G$8*12 -> 5298146 | G17: =G15*Assumptions!$G$8*12 -> 12270385
B18: PPV transactions | C18: =C11*Assumptions!$G$14*Assumptions!$G$48 -> 7200 | D18: =D11*Assumptions!$G$14*Assumptions!$G$49 -> 33600 | E18: =E11*Assumptions!$G$14*Assumptions!$G$50 -> 128000 | F18: =F11*Assumptions!$G$14*Assumptions!$G$51 -> 360000 | G18: =G11*Assumptions!$G$14*Assumptions!$G$52 -> 800000
B19: PPV billings | C19: =C18*Assumptions!$G$7 -> 35928 | D19: =D18*Assumptions!$G$7 -> 167664 | E19: =E18*Assumptions!$G$7 -> 638720 | F19: =F18*Assumptions!$G$7 -> 1796400 | G19: =G18*Assumptions!$G$7 -> 3992000
B20: Ad monetization ramp (input) | C20: 0 | D20: 0 | E20: 0.25 | F20: 0.6 | G20: 1
B21: Advertising revenue (net) | C21: =C11*Assumptions!$G$12*C20 -> 0 | D21: =D11*Assumptions!$G$12*D20 -> 0 | E21: =E11*Assumptions!$G$12*E20 -> 240000 | F21: =F11*Assumptions!$G$12*F20 -> 1440000 | G21: =G11*Assumptions!$G$12*G20 -> 4800000
B22: Featured placement & creator promo | C22: =C7*Assumptions!$G$13 -> 8250 | D22: =D7*Assumptions!$G$13 -> 28050 | E22: =E7*Assumptions!$G$13 -> 74250 | F22: =F7*Assumptions!$G$13 -> 156750 | G22: =G7*Assumptions!$G$13 -> 288750
B23: TOTAL GROSS BILLINGS | C23: =C17+C19+C21+C22 -> 116849.65 | D23: =D17+D19+D21+D22 -> 671006.24 | E23: =E17+E19+E21+E22 -> 2816558.4 | F23: =F17+F19+F21+F22 -> 8691296 | G23: =G17+G19+G21+G22 -> 21351135
B24: CREATOR PAYOUTS
B25: PPV payouts to creators | C25: =C19*Assumptions!$G$9 -> 12934.08 | D25: =D19*Assumptions!$G$9 -> 60359.04 | E25: =E19*Assumptions!$G$9 -> 229939.2 | F25: =F19*Assumptions!$G$9 -> 646704 | G25: =G19*Assumptions!$G$9 -> 1437120
B26: Subscription pool payouts | C26: =C17*Assumptions!$G$10 -> 32702.241 | D26: =D17*Assumptions!$G$10 -> 213881.51 | E26: =E17*Assumptions!$G$10 -> 838614.79 | F26: =F17*Assumptions!$G$10 -> 2384165.7 | G26: =G17*Assumptions!$G$10 -> 5521673.2
B27: Total creator payouts | C27: =C25+C26 -> 45636.321 | D27: =D25+D26 -> 274240.55 | E27: =E25+E26 -> 1068554 | F27: =F25+F26 -> 3030869.7 | G27: =G25+G26 -> 6958793.2
B28: NET REVENUE (platform take) | C28: =C23-C27 -> 71213.326 | D28: =D23-D27 -> 396765.69 | E28: =E23-E27 -> 1748004.4 | F28: =F23-F27 -> 5660426.3 | G28: =G23-G27 -> 14392342
B29: Net revenue growth (YoY) | C29: ="" | D29: =D28/C28-1 -> 4.5715091 | E29: =E28/D28-1 -> 3.405634 | F29: =F28/E28-1 -> 2.2382219 | G29: =G28/F28-1 -> 1.542625
B30: COST OF REVENUE
B31: Payment processing | C31: =C23*Assumptions!$G$11 -> 5258.2341 | D31: =D23*Assumptions!$G$11 -> 30195.281 | E31: =E23*Assumptions!$G$11 -> 126745.13 | F31: =F23*Assumptions!$G$11 -> 391108.32 | G31: =G23*Assumptions!$G$11 -> 960801.07
B32: Streaming, CDN & delivery | C32: =C15*Assumptions!$G$18*12*Assumptions!$G$19+C18*2*Assumptions!$G$19 -> 4214.13 | D32: =D15*Assumptions!$G$18*12*Assumptions!$G$19+D18*2*Assumptions!$G$19 -> 26482.355 | E32: =E15*Assumptions!$G$18*12*Assumptions!$G$19+E18*2*Assumptions!$G$19 -> 103536.04 | F32: =F15*Assumptions!$G$18*12*Assumptions!$G$19+F18*2*Assumptions!$G$19 -> 294038.85 | G32: =G15*Assumptions!$G$18*12*Assumptions!$G$19+G18*2*Assumptions!$G$19 -> 678287.1
B33: Storage & transcoding | C33: =C9*Assumptions!$G$25 -> 3850 | D33: =D9*Assumptions!$G$25 -> 16940 | E33: =E9*Assumptions!$G$25 -> 51590 | F33: =F9*Assumptions!$G$25 -> 124740 | G33: =G9*Assumptions!$G$25 -> 259490
B34: Moderation, review & content QA | C34: =C8*Assumptions!$G$24 -> 7700 | D34: =D8*Assumptions!$G$24 -> 26180 | E34: =E8*Assumptions!$G$24 -> 69300 | F34: =F8*Assumptions!$G$24 -> 146300 | G34: =G8*Assumptions!$G$24 -> 269500
B35: Total cost of revenue | C35: =C31+C32+C33+C34 -> 21022.364 | D35: =D31+D32+D33+D34 -> 99797.636 | E35: =E31+E32+E33+E34 -> 351171.17 | F35: =F31+F32+F33+F34 -> 956187.17 | G35: =G31+G32+G33+G34 -> 2168078.2
B36: GROSS PROFIT | C36: =C28-C35 -> 50190.962 | D36: =D28-D35 -> 296968.06 | E36: =E28-E35 -> 1396833.3 | F36: =F28-F35 -> 4704239.2 | G36: =G28-G35 -> 12224264
B37: Gross margin (% of net revenue) | C37: =C36/C28 -> 0.70479733 | D37: =D36/D28 -> 0.74847211 | E37: =E36/E28 -> 0.79910167 | F37: =F36/F28 -> 0.83107506 | G37: =G36/G28 -> 0.8493589
B38: OPERATING EXPENSES
B39: Headcount (avg. FTEs) | C39: =Assumptions!$G$63 -> 6 | D39: =Assumptions!$G$64 -> 12 | E39: =Assumptions!$G$65 -> 22 | F39: =Assumptions!$G$66 -> 36 | G39: =Assumptions!$G$67 -> 48
B40: Payroll & benefits | C40: =C39*Assumptions!$G$27*1000 -> 870000 | D40: =D39*Assumptions!$G$27*1000 -> 1740000 | E40: =E39*Assumptions!$G$27*1000 -> 3190000 | F40: =F39*Assumptions!$G$27*1000 -> 5220000 | G40: =G39*Assumptions!$G$27*1000 -> 6960000
B41: Creator acquisition | C41: =C6*Assumptions!$G$23 -> 20000 | D41: =D6*Assumptions!$G$23 -> 48000 | E41: =E6*Assumptions!$G$23 -> 112000 | F41: =F6*Assumptions!$G$23 -> 200000 | G41: =G6*Assumptions!$G$23 -> 320000
...

Sheet Market
B1: Market Analysis — TAM / SAM / SOM
B3: Market | C3: 2026 size (est.) | D3: 2030–32 size (est.) | E3: CAGR (est.) | G3: Source / basis
B4: AI video generation tools | C4: $3.2B | D4: $14–16B (2030) | E4: 28–35% | G4: Grand View Research / MarketsandMarkets AI video generator reports (2024–25); Sora/Veo/Runway commercial launches accelerated 2025–26
B5: Global video streaming (OTT) | C5: $720B | D5: $1.9T (2030) | E5: ~19–21% | G5: Grand View Research video streaming market report; includes SVOD, AVOD, FAST
B6: Creator economy | C6: $250–300B | D6: $480–600B (2030) | E6: ~12–15% | G6: Goldman Sachs creator economy research (2023, updated trajectories); SignalFire / Linktree creator reports
B7: Independent film production & distribution | C7: $15–20B | D7: $25–30B (2030) | E7: ~6–8% | G7: IBISWorld / Statista independent film segment; theatrical + digital self-distribution
B8: AI-generated entertainment content (nascent) | C8: $1–2B | D8: $10–25B (2030) | E8: >50% (from small base) | G8: Bottom-up: AI tool subscription base × content output × monetization rates; no established analyst category yet — early-stage estimate
B10: YOUMAKETV TAM / SAM / SOM BUILD (bottom-up)
B11: TAM — Total Addressable Market | C11: $45B | D11: Global premium on-demand video spend addressable by independent/AI content: ~6% of $720B streaming market (indie + niche SVOD + transactional VOD) + creator-monetization tooling.
B12: SAM — Serviceable Addressable Market | C12: $3.5B | D12: Direct monetization of AI-native film/video content (PPV + niche SVOD + creator services) in English-speaking + EU markets over next 5 years.
B13: SOM — Serviceable Obtainable Market (Yr 5) | C13: $60–110M gross billings | D13: Base-to-aggressive Year-5 gross billings from the Model represent ~0.5–3% share of SAM; Base case models ~$21M gross billings — deliberately below SOM ceiling.
B15: KEY TRENDS
B16: • Cost of producing a watchable short film has collapsed from ~$50K+ to <$500 in tooling/compute (Sora, Veo 3, Runway Gen-4, Kling 2.x) — supply of AI films is exploding.
B17: • No incumbent platform treats AI films as a first-class category: YouTube buries them in general content; Netflix/Prime don't accept them; tool vendors (Runway, Pika) monetize creation, not distribution.
B18: • Creator economy monetization is shifting from ad-share to direct fan monetization (memberships, PPV) — favorable to a take-rate marketplace.
B19: • Regulatory pressure (AI labeling, provenance) favors a curated, compliance-first platform over open uploads.
B20: • FAST/AVOD growth shows audiences accept new low-cost content brands when discovery is good.

Sheet Competition
B1: Competitive Landscape
B3: Player | C3: Type | D3: Strengths | E3: Weaknesses | F3: Opportunity for YouMakeTV
B4: YouTube | C4: UGC / ads | D4: Massive reach (2.5B+ MAU); free; best-in-class discovery & infra; Shorts funnel | E4: AI films buried among all content; ad-share economics weak for long-form niche ($1–3 RPM); no PPV-first model; algorithm punishes low-sub channels | F4: Position as the premium, curated home where AI filmmakers actually earn per view, not per ad impression. Use YouTube as a trailer/funnel channel, not a competitor for the catalog.
B5: Vimeo OTT | C5: White-label VOD | D5: Mature paywall tech; creator keeps ~90%; strong player/infra | E5: No audience — creators bring 100% of traffic; declining consumer brand; expensive for small creators | F5: YouMakeTV provides the audience + marketplace discovery Vimeo never built. Target Vimeo OTT churners.
B6: Patreon | C6: Membership | D6: 8M+ paying members; recurring revenue mechanics; creator loyalty | E6: Not a viewing destination; no discovery; video experience poor; membership ≠ per-title sales | F6: Integrate membership-style follows with actual streaming. Patreon creators with film projects are a prime acquisition list.
B7: Kickstarter | C7: Crowdfunding | D7: Proven film-funding behavior; project discovery | E7: One-shot funding, no distribution or recurring monetization | F7: Partner/funnel: films funded on Kickstarter need a distribution home; AI films rarely fit its norms.
B8: Netflix | C8: Premium SVOD | D8: Brand, $17B+ content budget, global subs (300M+) | E8: Closed; does not accept indie/AI submissions; experimenting with AI internally but not as a marketplace | F8: Be the open marketplace Netflix structurally cannot be. Long-term: license breakout AI titles upward.
B9: Prime Video Direct | C9: Open VOD | D9: Huge audience; self-serve uploads | E9: Has been cutting royalty rates & rejecting low-engagement content; AI content explicitly restricted/limited; opaque payouts | F9: Creators rejected or demonetized by PVD are actively seeking alternatives — a real, motivated segment.
B10: TikTok | C10: Short video | D10: Distribution engine; AI content thrives; huge Gen-Z reach | E10: No long-form monetization; no PPV; creator fund economics weak; ban/regulatory risk in US | F10: Use as top-of-funnel (trailers, clips). Not a destination for films.
B11: Reelmind / AI video communities | C11: AI-native UGC | D11: AI-native positioning; early communities | E11: Tool-first, monetization shallow; tiny audiences; no curation/QC | F11: Out-execute on curation, payouts, and viewer experience; acquire their frustrated creators.
B12: Runway / Pika / Luma / Kling | C12: Creation tools | D12: Own the creator relationship; strong brands in AI video; festivals (Runway AIFF) | E12: They monetize creation (subscriptions/credits), not distribution; no consumer viewing destination; conflicted about ranking one user's film over another's | F12: Natural partners, not competitors: "made with Runway → distributed on YouMakeTV." Co-marketing, festival pipelines, export integrations.
B13: OpenAI Sora ecosystem | C13: Creation tool + feed | D13: State-of-the-art generation; Sora app has a social feed; massive attention | E13: Feed is social/remix-oriented, not film-length; no creator payouts at scale yet; OpenAI ambitions uncertain — could become a competitor | F13: Move fast to own "AI films as premium content" before a tool vendor verticalizes. Biggest strategic risk AND biggest validation.
B14: Emerging AI film platforms (e.g., AI film festivals, niche curators) | C14: Curation | D14: Community credibility; early-mover taste-making | E14: No tech moat, no payments/streaming infra, mostly events not platforms | F14: Acquire or partner for curation brand + creator lists; YouMakeTV supplies the rails.
B16: POSITIONING MATRIX (✔ = strong, ~ = partial, ✘ = none)
B17: Capability | C17: YouTube | D17: Vimeo OTT | E17: Tool vendors | F17: YouMakeTV
B18: AI-native curated catalog | C18: ✘ | D18: ✘ | E18: ~ | F18: ✔
B19: Per-title (PPV) monetization | C19: ~ (rentals, limited) | D19: ✔ | E19: ✘ | F19: ✔
B20: Subscription bundle for viewers | C20: ~ (Premium, not AI) | D20: ✘ | E20: ✘ | F20: ✔
B21: Creator revenue share that scales with success | C21: ✘ (flat 55%) | D21: ✔ (but no audience) | E21: ✘ | F21: ✔ (30→40% tiers)
B22: Built-in audience / discovery | C22: ✔ | D22: ✘ | E22: ~ (tool users) | F22: Building — the core execution risk
B23: Human review / quality gate | C23: ✘ | D23: ✘ | E23: ✘ | F23: ✔

Sheet GTM-Creators
B1: Creator Acquisition — Channel Plan (Year 1)
B2: Yellow = editable. Signups & CAC are formulas.
B4: Channel | C4: Est. addressable reach | D4: Engaged / mo | E4: Click/visit rate | F4: Visit→signup | G4: Annual cost ($) | H4: Expected signups | I4: CAC ($) | J4: Notes / tactics
B5: Runway community & AIFF film festival | C5: 350000 | D5: 18000 | E5: 0.05 | F5: 0.06 | G5: 18000 | H5: =D5*12*E5*F5 -> 648 | I5: =IF(H5>0,G5/H5,"-") -> 28 | J5: Festival sponsorship, Discord presence, "distribute your AIFF entry" campaign
B6: OpenAI Sora creators (feed + Discord/X) | C6: 600000 | D6: 40000 | E6: 0.03 | F6: 0.05 | G6: 15000 | H6: =D6*12*E6*F6 -> 720 | I6: =IF(H6>0,G6/H6,"-") -> 21 | J6: X engagement, showcase reposts, "Sora-to-screen" onboarding guides
B7: Pika / Luma / Kling user communities | C7: 450000 | D7: 25000 | E7: 0.04 | F7: 0.05 | G7: 12000 | H7: =D7*12*E7*F7 -> 600 | I7: =IF(H7>0,G7/H7,"-") -> 20 | J7: Discord partnerships, creator challenges with cash prizes
B8: Midjourney cinematic community | C8: 800000 | D8: 30000 | E8: 0.02 | F8: 0.04 | G8: 8000 | H8: =D8*12*E8*F8 -> 288 | I8: =IF(H8>0,G8/H8,"-") -> 28 | J8: Targets storyboard/cinematic prompt artists moving into video
B9: ComfyUI / Stable Diffusion / Flux (open-source) | C9: 500000 | D9: 35000 | E9: 0.04 | F9: 0.07 | G9: 10000 | H9: =D9*12*E9*F9 -> 1176 | I9: =IF(H9>0,G9/H9,"-") -> 9 | J9: GitHub/Reddit presence; workflow-to-film tutorials; highest technical skill density
B10: Reddit (r/aivideo, r/StableDiffusion, r/Filmmakers…) | C10: 2500000 | D10: 120000 | E10: 0.015 | F10: 0.04 | G10: 9000 | H10: =D10*12*E10*F10 -> 864 | I10: =IF(H10>0,G10/H10,"-") -> 10 | J10: Organic posts + modest promoted posts; AMA with founding creators
B11: Discord servers (AI art/video, 50+ servers) | C11: 400000 | D11: 60000 | E11: 0.03 | F11: 0.06 | G11: 7000 | H11: =D11*12*E11*F11 -> 1296 | I11: =IF(H11>0,G11/H11,"-") -> 5 | J11: Server partnerships, screening-night events, bot integrations
B12: X (AI film Twitter) | C12: 1500000 | D12: 90000 | E12: 0.02 | F12: 0.04 | G12: 12000 | H12: =D12*12*E12*F12 -> 864 | I12: =IF(H12>0,G12/H12,"-") -> 14 | J12: Founder-led content, creator spotlights, revenue-share receipts ("first $1K paid out")
B13: Facebook groups & LinkedIn (AI video pros) | C13: 600000 | D13: 25000 | E13: 0.015 | F13: 0.03 | G13: 5000 | H13: =D13*12*E13*F13 -> 135 | I13: =IF(H13>0,G13/H13,"-") -> 37 | J13: Groups for AI filmmakers; LinkedIn for studio/agency creators
B14: Indie filmmaker communities (film schools, NoFilmSchool…) | C14: 900000 | D14: 30000 | E14: 0.01 | F14: 0.03 | G14: 8000 | H14: =D14*12*E14*F14 -> 108 | I14: =IF(H14>0,G14/H14,"-") -> 74 | J14: Hybrid filmmakers adopting AI tools; festival-circuit outreach
B15: AI creator influencers (10–15 sponsorships) | C15: 3000000 | D15: 150000 | E15: 0.012 | F15: 0.05 | G15: 36000 | H15: =D15*12*E15*F15 -> 1080 | I15: =IF(H15>0,G15/H15,"-") -> 33 | J15: $1.5–3K per sponsored video/thread; mid-tier (50–300K followers) AI-tool educators
B16: TOTAL YEAR 1 | G16: =SUM(G5:G15) -> 140000 | H16: =SUM(H5:H15) -> 7779 | I16: =G16/H16 -> 18
B18: FUNNEL ASSUMPTIONS & ACTIVATION
B19: • Activation (signup → publishes ≥1 approved film): 45–65% — driven by white-glove onboarding for first 200 creators.
B20: • These channel totals intentionally exceed the Model's Base-case 500 Year-1 signups (~2x buffer) — channels underperform, plans shouldn't.
B21: • First 50 creators: founder-led direct recruitment (hand-picked from festival winners & viral AI shorts). CAC ≈ $0 cash, high founder time.
B22: • Creator referral program from Month 6: $50 bonus per activated referral — expected to become the cheapest channel by Year 2.
B23: • Influencer ROI check: $36K → ~1,080 signups → ~$33 CAC; vs. blended target $40. Kill any channel >$80 CAC after 2 quarters.

Sheet GTM-Viewers
B1: Viewer Acquisition — Channel Plan (Year 1 → Year 2)
B4: Channel | C4: Y1 budget ($) | D4: CPM ($) | E4: CTR | F4: Visit→signup | G4: Signup→paid | H4: Paying users | I4: CAC ($) | J4: Notes
B5: Paid search (Google) | C5: 60000 | H5: 1000 | I5: =C5/H5 -> 58 | J5: High-intent: "watch AI films", "AI movies". Modeled directly: ~$2.5 CPC, 12% signup, 18% paid → ~1,000 payers, CAC ≈ $58. Small market today, grows with category.
B6: Meta / Instagram Reels ads | C6: 90000 | D6: 9 | E6: 0.012 | F6: 0.1 | G6: 0.1 | H6: =C6/D6*1000*E6*F6*G6 -> 1200 | I6: =IF(H6>0,C6/H6,"-") -> 75 | J6: Trailer-led creative; retarget video viewers
B7: TikTok ads | C7: 60000 | D7: 6 | E7: 0.015 | F7: 0.08 | G7: 0.08 | H7: =C7/D7*1000*E7*F7*G7 -> 960 | I7: =IF(H7>0,C7/H7,"-") -> 63 | J7: Clips + creator duets; younger demo, lower intent
B8: YouTube ads (trailer pre-roll) | C8: 80000 | D8: 12 | E8: 0.01 | F8: 0.12 | G8: 0.12 | H8: =C8/D8*1000*E8*F8*G8 -> 960 | I8: =IF(H8>0,C8/H8,"-") -> 83 | J8: In-feed trailer promotion to film/AI-interest audiences
B9: Display / programmatic | C9: 20000 | D9: 4 | E9: 0.002 | F9: 0.05 | G9: 0.05 | H9: =C9/D9*1000*E9*F9*G9 -> 25 | I9: =IF(H9>0,C9/H9,"-") -> 800 | J9: Cheap reach, weak intent — capped test budget
B10: Retargeting (all platforms) | C10: 30000 | D10: 7 | E10: 0.025 | F10: 0.18 | G10: 0.22 | H10: =C10/D10*1000*E10*F10*G10 -> 4243 | I10: =IF(H10>0,C10/H10,"-") -> 7 | J10: Highest-converting paid channel; needs pixel base first
B11: SEO & content hub | C11: 25000 | H11: 1400 | I11: =C11/H11 -> 18 | J11: "Best AI films 2026", creator pages, film pages. 6–12 mo lag; compounding. Est. 120K organic visits Y1 → ~1,400 payers.
B12: Owned YouTube + Shorts | C12: 30000 | H12: 1600 | I12: =C12/H12 -> 19 | J12: Trailer channel + weekly "best of AI film" shows; 2 editors part-time. Est. 2M views Y1 → ~1,600 payers.
B13: Owned TikTok / Reels | C13: 20000 | H13: 900 | I13: =C13/H13 -> 22 | J13: Clip factory from catalog (with creator consent); viral upside not modeled.
B14: Influencers (film/AI reviewers) | C14: 45000 | H14: 1500 | I14: =C14/H14 -> 30 | J14: 8–12 sponsorships; "I watched 20 AI films" format. CPM-equivalent ~$15, but conversion 2–3x paid ads.
B15: Affiliates (creators as affiliates) | C15: 15000 | H15: 2500 | I15: =C15/H15 -> 6 | J15: 20% of first-year revenue to referring creator — creators bring their own audience; the structural answer to cold start.
B16: PR & festivals | C16: 30000 | H16: 700 | I16: =C16/H16 -> 43 | J16: Launch story ("the Netflix of AI film"), festival partnerships, awards show. Drives brand search baseline.
B17: TOTAL | C17: =SUM(C5:C16) -> 505000 | H17: =SUM(H5:H16) -> 13000 | I17: =C17/H17 -> 39
B19: NOTES
B20: • This plan front-loads the full Year-1 + part of Year-2 marketing budget vs. the Model (Model Year 1 marketing ≈ $164K Base). Spend gates open only after activation metrics (D7 retention >25%, trailer→watch >15%) are hit — do not buy traffic into a leaky funnel.
B21: • "Paying users" mixes subscribers and PPV buyers; blended target CAC ≤ $40, subscriber-only CAC ≤ $25 by Year 2.
B22: • Retargeting and affiliates are the two channels expected to beat $20 CAC at scale; both require an existing traffic/creator base — hence paid social leads in H1.
B23: • CPM/CTR/conversion cells are editable; benchmarks from 2025 Meta/TikTok/YouTube performance norms for entertainment apps.

Sheet Bootstrapping
B1: Marketplace Cold-Start Plan — Solving "Creators need viewers, viewers need content"
C3: PHASE 1 — Seed supply (Months 0–6) | D3: PHASE 2 — Prove demand (Months 6–18) | E3: PHASE 3 — Network effects (Months 18–36)
B4: Core principle | C4: Supply first. A film catalog is inventory that doesn't churn — viewers do. Curate 150–300 genuinely good films before spending $1 on viewer ads. | D4: Concentrate demand. Drive all traffic to a small, high-quality catalog so every film gets views and every creator gets paid something. | E4: Let creators bring viewers and viewers attract creators. Referral loops, payout screenshots, and franchise/series content compound.
B5: Creator targets | C5: 50 hand-picked founding creators (festival winners, viral AI shorts); 150–300 films live; guaranteed placement + 0% take on first $500 each ("Founding Creator" deal). | D5: 300–500 active creators; 1,000–1,800 films; first creators crossing Growth tier (1,000 paid views) — publicize every milestone. | E5: 1,500–3,000 active creators; 5,000–12,000 films; top creators earning $2–5K/mo; Pro-tier creators become platform evangelists.
B6: Viewer targets | C6: 3–5K registered (waitlist + creators' own audiences). Goal is engagement data, not scale: D7 retention >25%, >15% trailer→film conversion. | D6: 30–120K registered; 1.5–8K subscribers; prove CAC ≤ $35 and M3 subscriber retention >55% before scaling spend. | E6: 300K–1M registered; 30K+ subscribers; organic/referral share of signups >40%.
B7: Liquidity mechanics | C7: Every approved film guaranteed ≥500 impressions in-app; weekly themed premieres create appointment viewing despite a small catalog. | D7: Editorial front page (human-curated rows); "new this week" velocity; affiliate links so creators earn 20% of referred first-year revenue. | E7: Personalized discovery; genre verticals (AI horror, sci-fi shorts, animation); seasons/series retain viewers between releases.
B8: Chicken-and-egg answer | C8: Creators don't need viewers yet — they need DISTRIBUTION + LEGITIMACY. A curated platform that says "your film is good" plus guaranteed placement is enough to seed supply at near-zero cost. | D8: Viewers don't need a huge catalog — they need 20 great hours in their genre. 300 curated films ≈ a niche streamer's launch catalog (Shudder launched with <200 titles). | E8: At ~1,000 films / 30K subscribers the flywheel turns: payouts attract creators organically (CAC→$0), catalog breadth lifts retention, retention lifts LTV, LTV funds growth.
B9: Kill / pivot signals | C9: If <40% of invited creators publish, the value prop is wrong — fix payouts/onboarding before scaling. | D9: If subscriber M3 retention <40% despite curation, the standalone-destination thesis fails → pivot to B2B licensing / white-label. | E9: If CAC won't drop below $30 blended, raise prices or shift to AVOD-first model.
B11: MINIMUM VIABLE LIQUIDITY — what it takes before network effects start
B12: Dimension | C12: Threshold | D12: Rationale
B13: Films | C13: ≈ 1,000 quality titles | D13: Comparable niche streamers (Shudder, Dropout) demonstrate retention with 200–600 titles; 1,000 gives genre depth.
B14: Active creators | C14: ≈ 400–600 | D14: At 3.5 films/creator/yr this sustains ~30 new releases/week — enough "newness" for weekly visits.
B15: Subscribers | C15: ≈ 25–30K | D15: At $7.99/mo this is ~$2.4–2.9M ARR — funds meaningful creator pool payouts ($1M+/yr), which makes the platform self-evidently worth creators' time.
B16: Timeline | C16: Months 24–30 (Base case) | D16: Matches Model: Year-3 exit ≈ 30K subscribers, ~2,500 active creators, ~13K films.

Sheet UnitEcon
B1: Unit Economics — CAC / LTV / Payback
C3: Worst | D3: Base | E3: Best | F3: Method
B4: SUBSCRIBERS (YouMake+)
B5: Net ARPU ($/mo, after creator pool share) | C5: 3.495 | D5: 4.3945 | E5: 5.394 | F5: Subscription price × platform share of sub revenue (50–60%)
B6: Contribution margin on net ARPU | C6: 0.7 | D6: 0.78 | E6: 0.82 | F6: After processing, streaming, storage, support allocations
B7: Monthly churn | C7: 0.09 | D7: 0.065 | E7: 0.045 | F7: Niche SVOD benchmark 5–10%/mo; improves with catalog depth
B8: CAC (blended) | C8: 35 | D8: 25 | E8: 16 | F8: From GTM-Viewers; best case = high organic/referral mix
B9: LTV | C9: =C5*C6/C7 -> 27.183333 | D9: =D5*D6/D7 -> 52.734 | E9: =E5*E6/E7 -> 98.290667 | F9: LTV = net ARPU × margin ÷ churn
B10: LTV : CAC | C10: =C9/C8 -> 0.77666667 | D10: =D9/D8 -> 2.10936 | E10: =E9/E8 -> 6.1431667 | F10: Target ≥ 3.0x at scale
B11: Payback (months) | C11: =C8/(C5*C6) -> 14.306152 | D11: =D8/(D5*D6) -> 7.2934992 | E11: =E8/(E5*E6) -> 3.6173888 | F11: CAC ÷ monthly contribution
B13: PAY-PER-VIEW BUYERS
B14: Net revenue per transaction | C14: 2.0349 | D14: 2.810368 | E14: 3.61197 | F14: Price × platform share (60–67%) × contribution margin
B15: Lifetime transactions per buyer | C15: 3 | D15: 6 | E15: 10 | F15: Repeat purchase behavior over ~24 months
B16: CAC (must be near-organic) | C16: 8 | D16: 4 | E16: 2 | F16: PPV cannot support paid CAC — acquired via SEO, creator affiliates, cross-sell
B17: LTV | C17: =C14*C15 -> 6.1047 | D17: =D14*D15 -> 16.862208 | E17: =E14*E15 -> 36.1197
B18: LTV : CAC | C18: =C17/C16 -> 0.7630875 | D18: =D17/D16 -> 4.215552 | E18: =E17/E16 -> 18.05985 | F18: PPV works only as an organic monetization layer + sub-conversion funnel
B20: CREATORS (as supply-side "customers")
B21: CAC per activated creator | C21: 130 | D21: 73 | E21: 46 | F21: Signup CAC ÷ activation rate (60/0.45, 40/0.55, 30/0.65)
B22: Films per creator over 24 months | C22: 4 | D22: 7 | E22: 9
B23: Platform net revenue per creator per year | C23: 100 | D23: 250 | E23: 600 | F23: Base ≈ Model Year-3 net revenue per active creator (~$640 by Y3, lower in Y1–2; $250 is a 24-mo blend)
B24: 24-month creator LTV (net revenue) | C24: =C23*2 -> 200 | D24: =D23*2 -> 500 | E24: =E23*2 -> 1200
B25: LTV : CAC | C25: =C24/C21 -> 1.5384615 | D25: =D24/D21 -> 6.8493151 | E25: =E24/E21 -> 26.086957 | F25: Healthy even in worst case — supply acquisition is cheap relative to its revenue yield
B27: READ-THROUGH
B28: • Subscriber economics clear the 3x LTV:CAC bar in Base case (≈3.2x) with ~7-month payback — fundable, not exceptional. The lever is churn: every point of monthly churn ≈ ±$11 LTV.
B29: • PPV is margin-rich but cannot absorb paid acquisition. Treat PPV as (1) monetization of organic traffic and (2) a stepping stone to subscription.
B30: • Creator-side LTV:CAC of ~7x in Base case is the quiet strength of the model: supply compounds (films stay in catalog) while demand churns.
B31: • Worst-case subscriber economics (1.1x LTV:CAC) are NOT viable — the model depends on pushing churn below ~7%/mo within 18 months. This is the #1 metric to underwrite.

Sheet Hiring
B1: Hiring Plan — Years 1–3 (Base case)
B3: Role | C3: Salary (fully loaded) | D3: Start | E3: Y1 FTE | F3: Y2 FTE | G3: Y3 FTE | H3: Notes
B4: CEO (founder) | C4: 120000 | D4: Day 1 | E4: 1 | F4: 1 | G4: 1 | H4: Below-market founder salary until Series A
B5: CTO (founder or founding eng.) | C5: 140000 | D5: Day 1 | E5: 1 | F5: 1 | G5: 1 | H5: Owns platform, infra, AI moderation pipeline
B6: Full-stack engineers | C6: 160000 | D6: M1 / M9 | E6: 1.5 | F6: 3 | G6: 5 | H6: Player, payments, dashboards, recommendation v1
B7: ML / moderation engineer | C7: 175000 | D7: M12 | E7: 0 | F7: 1 | G7: 2 | H7: Provenance detection, content QA automation, recsys
B8: Product designer | C8: 140000 | D8: M6 | E8: 0.5 | F8: 1 | G8: 1.5 | H8: Contract→FTE; viewer UX is the retention lever
B9: Head of Content / Curation | C9: 130000 | D9: M3 | E9: 0.8 | F9: 1 | G9: 1 | H9: Ex-festival programmer; owns quality bar & editorial
B10: Creator Success managers | C10: 95000 | D10: M4 / M14 | E10: 0.7 | F10: 2 | G10: 4 | H10: 1 per ~150 active creators; onboarding, payouts, retention
B11: Growth / performance marketer | C11: 135000 | D11: M8 | E11: 0.4 | F11: 1 | G11: 2 | H11: Owns paid + lifecycle; agency support in Y1
B12: Content & social lead | C12: 90000 | D12: M10 | E12: 0.2 | F12: 1 | G12: 2 | H12: Trailer channel, clips, newsletter
B13: Customer support | C13: 65000 | D13: M12 | E13: 0.1 | F13: 1 | G13: 2.5 | H13: Outsourced/part-time in Y1; in-house from Y2
B14: Finance / ops (fractional → FTE) | C14: 110000 | D14: M6 / M24 | E14: 0.3 | F14: 0.5 | G14: 1 | H14: Fractional CFO until Series A; payouts compliance
B15: Trust & safety / moderation ops | C15: 80000 | D15: M9 | E15: 0.5 | F15: 1.5 | G15: 3 | H15: Human review layer on top of AI screening
B16: TOTAL HEADCOUNT | E16: =SUM(E4:E15) -> 7 | F16: =SUM(F4:F15) -> 15 | G16: =SUM(G4:G15) -> 26
B17: TOTAL PAYROLL | E17: =SUMPRODUCT($C$4:$C$15,E4:E15) -> 892000 | F17: =SUMPRODUCT($C$4:$C$15,F4:F15) -> 1840000 | G17: =SUMPRODUCT($C$4:$C$15,G4:G15) -> 3092500
B19: Note: FTE figures are year-averages (0.5 = hired mid-year). Salaries are fully loaded (base + taxes + benefits + equipment), US-remote blend; 30–40% savings available via EU/LatAm engineering hires. Reconciles to Model payroll within ±10% (Model uses a single blended average).

Sheet UseOfFunds
B1: Use of Funds — Recommended $4.0M Seed (24-month plan)
B3: Round size ($): | C3: 4000000
B5: Category | C5: % allocation | D5: Amount ($) | E5: What it buys
B6: Engineering & Product | C6: 0.38 | D6: =C6*$C$3 -> 1520000 | E6: Core team of 4–5 engineers + design: recommendation engine, payout infrastructure, apps (web → TV → mobile), creator analytics dashboard
B7: Growth & Marketing | C7: 0.24 | D7: =C7*$C$3 -> 960000 | E7: Creator + viewer acquisition per GTM sheets; performance budget gated on retention milestones
B8: Content & Creator Success | C8: 0.14 | D8: =C8*$C$3 -> 560000 | E8: Founding-creator incentives, curation team, festival/community programs, creator success managers
B9: Trust, Safety & Moderation | C9: 0.08 | D9: =C9*$C$3 -> 320000 | E9: Human review ops, AI screening tooling, provenance verification, copyright claim handling
B10: Infrastructure | C10: 0.06 | D10: =C10*$C$3 -> 240000 | E10: Streaming/CDN, storage, transcoding capacity ahead of growth
B11: Legal & Compliance | C11: 0.05 | D11: =C11*$C$3 -> 200000 | E11: Content licensing framework, AI-content policy counsel, payout/KYC compliance, entity & IP
B12: Operations & Buffer | C12: 0.05 | D12: =C12*$C$3 -> 200000 | E12: Finance ops, insurance, contingency
B13: TOTAL | C13: =SUM(C6:C12) -> 1 | D13: =SUM(D6:D12) -> 4000000

Sheet Valuation
B1: Valuation Framework
B3: Round | C3: Timing / milestone | D3: Valuation (post-money) | E3: Dilution | F3: Basis & comparables
B4: Pre-seed / angel (if taken) | C4: Now: MVP live, pre-traction | D4: $5–8M cap (SAFE) | E4: 10–15% | F4: 2025–26 US pre-seed medians ~$5–7M cap (Carta); AI-adjacent consumer premium ~20–30%; no traction discount offsets it. Comparable: typical pre-revenue marketplace SAFEs.
B5: SEED (recommended now) | C5: MVP + first 50–100 founding creators signed | D5: $14–18M post ($4M on $10–14M pre) | E5: ~22–28% | F5: Carta 2025 seed medians: ~$15M post for consumer/marketplace; AI-content platforms command upper band. Comps at seed stage: Patreon ($2.1M seed, 2013-era pricing — adjust 3–4x), Nebula (bootstrapped to ~$50M val), early Vimeo OTT.
B6: Series A | C6: Month 20–28: $1.5–2.5M ARR, 4–5x YoY growth, churn <7%/mo, 1,000+ films | D6: $45–70M post ($9–12M raise) | E6: ~18–22% | F6: 8–15x forward net-revenue multiple for marketplace + AI premium. Comps: consumer subscription As at $2M ARR ≈ $40–60M (2024–25 vintage); Curiosity Stream IPO'd at ~5x revenue (mature, low growth — YouMakeTV at A should price on growth).
B7: Series B (illustrative) | C7: Year 4: $8–12M net revenue run-rate | D7: $120–200M | E7: ~15–20% | F7: Dependent on take-rate durability and EBITDA trajectory; only if Series A milestones beat plan.
B9: ASSUMPTIONS & HONEST CAVEATS
B10: • These valuations assume the milestone column is MET. Pre-traction, the company is worth what seed investors will pay for team + thesis + working product: $10–14M pre is the defensible range in mid-2026, not higher.
B11: • AI-content platforms currently enjoy a sentiment premium; it may compress. The model's Base case supports a Series A on metrics (not hype) by Month ~24–28.
B12: • Anchor on NET revenue multiples. Quoting gross billings multiples will damage credibility with marketplace-literate investors.
B13: • Founder dilution through Series A ≈ 40–45% cumulative (incl. ~10% ESOP refresh). Plan accordingly.

Sheet Risks
B1: Risk Register
B3: Risk | C3: Likelihood | D3: Impact | E3: Description | F3: Mitigation
B4: Copyright & IP | C4: High | D4: High | E4: AI films may embed copyrighted characters, music, or likenesses; training-data litigation (e.g., studios vs. AI vendors) could create downstream liability for distributors. | F4: Pre-publication review (already built); automated music/character fingerprinting; creator warranties + indemnification in ToS; DMCA-compliant takedown; E&O insurance; "provenance required" metadata. Budgeted legal line grows 2.8x by Y5.
B5: AI regulation | C5: Medium-High | D5: Medium | E5: EU AI Act transparency rules (in force, content-labeling obligations phasing through 2026–27), US state laws (deepfake/likeness), mandatory AI-content labeling. | F5: Labeling AI content is YouMakeTV's default — regulation that burdens general platforms is a tailwind for a compliance-native one. Counsel on retainer; geo-gating capability.
B6: Moderation failures | C6: Medium | D6: High | E6: Deepfakes of real people, CSAM-adjacent generated content, extremist content — a single scandal could kill distribution partnerships and app-store presence. | F6: Human review of 100% of titles pre-publication (feasible to ~30K films/yr); AI screening layer; likeness-verification for real-person depictions; strict creator identity (KYC at payout).
B7: Fraud | C7: Medium | D7: Medium | E7: View-count fraud to game revenue tiers; stolen-card PPV purchases; self-dealing (creators buying own content); chargebacks. | F7: Paid-view definition requires watch-time + payment settlement; payout holds (30 days); device/IP anomaly detection; KYC; chargeback reserves in payout terms.
B8: Content quality / lemon market | C8: High | D8: Medium | E8: AI tools produce vastly more mediocre content than good; a flooded catalog destroys viewer trust (the "Spotify AI slop" problem). | F8: Curation IS the product: approval gate, editorial front page, quality-weighted discovery, tiered placement. Reject rate expected 60–80% early. This is the core defensibility thesis.
B9: Competition (tool vendors verticalize) | C9: Medium-High | D9: High | E9: OpenAI (Sora feed), Runway, or YouTube could launch an AI-film destination with vastly more resources and built-in supply. | F9: Speed to liquidity + multi-tool neutrality (creators don't want their distribution owned by one tool vendor); curation brand; creator payout relationships. Partner aggressively with 2nd-tier tools who need a distribution story.
B10: Funding risk | C10: Medium | D10: High | E10: Consumer/marketplace seed appetite is selective; Series A requires real retention metrics in ~24 months; AI premium may fade. | F10: Raise 24 months of runway (not 18); gate spend on retention milestones; maintain B2B licensing pivot option (white-label AI content library) as a revenue backstop.
B11: Demand risk (do viewers want AI films?) | C11: Medium-High | D11: Very High | E11: The unproven core assumption: will consumers pay to watch AI-generated films at scale? Current evidence is anecdotal (viral shorts), not transactional. | F11: This is what the seed round exists to answer. Phase-gated spending: no scale marketing until D7 retention >25% and M3 sub retention >55% are proven on a small base. Honest kill criteria defined in Bootstrapping sheet.
